<?xml version="1.0" ?>
<!-- =================================================================================== -->
<!-- |    This document was autogenerated by xacro from /home/anton/ws_moveit/src/third_party/fanuc/fanuc_lrmate200id_support/urdf/test/lrmate200id.xacro | -->
<!-- |    EDITING THIS FILE BY HAND IS NOT RECOMMENDED                                 | -->
<!-- =================================================================================== -->
<robot name="fanuc_lrmate200id" xmlns:controller="http://playerstage.sourceforge.net/gazebo/xmlschema/#controller" xmlns:interface="http://playerstage.sourceforge.net/gazebo/xmlschema/#interface" xmlns:sensor="http://playerstage.sourceforge.net/gazebo/xmlschema/#sensor">
    <!--##############################################################################-->
    <link name="base_link">
        <visual>
            <origin rpy="0 0 0" xyz="0 0 0" />
            <geometry>
                <mesh filename="package://fanuc_lrmate200id_support/meshes/lrmate200id/visual/base_link.stl" />
            </geometry>
            <material name="">
                <color rgba="0.2784313725490196 0.2784313725490196 0.2784313725490196 1.0" />
            </material>
        </visual>
        <collision>
            <origin rpy="0 0 0" xyz="0 0 0" />
            <geometry>
                <mesh filename="package://fanuc_lrmate200id_support/meshes/lrmate200id/collision/base_link.stl" />
            </geometry>
        </collision>
        <inertial>
            <origin rpy="0 0 0" xyz="0 0 0" />
            <mass value="10.0" />
            <inertia ixx="0.1" ixy="0.0" ixz="0.0" iyy="0.1" iyz="0.0" izz="0.1" />
        </inertial>
    </link>
    <link name="world" />
    <joint name="base_link_to_world_joint" type="fixed">
        <!-- <origin xyz="0 0 0.330" rpy="0 0 0"/> -->
        <parent link="world" />
        <child link="base_link" />
    </joint>
    <!--##############################################################################-->
    <gazebo>
        <plugin filename="libgazebo_ros_control.so" name="gazebo_ros_control">
            <robotNamespace>/</robotNamespace>
            <robotSimType>gazebo_ros_control/DefaultRobotHWSim</robotSimType>
            <legacyModeNS>false</legacyModeNS>
        </plugin>
        <plugin filename="libgazebo_ros_planar_move.so" name="object_controller">
            <commandTopic>cmd_vel</commandTopic>
            <odometryTopic>world</odometryTopic>
            <odometryFrame>world</odometryFrame>
            <odometryRate>50.0</odometryRate>
            <robotBaseFrame>base_link</robotBaseFrame>
        </plugin>
    </gazebo>
    <!--###########################################LINK###################################-->
    <link name="link_1">
        <visual>
            <origin rpy="0 0 0" xyz="0 0 0" />
            <geometry>
                <mesh filename="package://fanuc_lrmate200id_support/meshes/lrmate200id/visual/link_1.stl" />
            </geometry>
            <material name="">
                <color rgba="0.96 0.76 0.13 1.0" />
            </material>
        </visual>
        <collision>
            <origin rpy="0 0 0" xyz="0 0 0" />
            <geometry>
                <mesh filename="package://fanuc_lrmate200id_support/meshes/lrmate200id/collision/link_1.stl" />
            </geometry>
        </collision>
        <inertial>
            <origin rpy="0 0 0" xyz="0 0 0" />
            <mass value="2.0" />
            <inertia ixx="0.01" ixy="0.0" ixz="0.0" iyy="0.01" iyz="0.0" izz="0.01" />
        </inertial>
    </link>
    <link name="link_2">
        <visual>
            <origin rpy="0 0 0" xyz="0 0 0" />
            <geometry>
                <mesh filename="package://fanuc_lrmate200id_support/meshes/lrmate200id/visual/link_2.stl" />
            </geometry>
            <material name="">
                <color rgba="0.96 0.76 0.13 1.0" />
            </material>
        </visual>
        <collision>
            <origin rpy="0 0 0" xyz="0 0 0" />
            <geometry>
                <mesh filename="package://fanuc_lrmate200id_support/meshes/lrmate200id/collision/link_2.stl" />
            </geometry>
        </collision>
        <inertial>
            <origin rpy="0 0 0" xyz="0 0 0" />
            <mass value="1.5" />
            <inertia ixx="0.008" ixy="0.0" ixz="0.0" iyy="0.008" iyz="0.0" izz="0.008" />
        </inertial>
    </link>
    <link name="link_3">
        <visual>
            <origin rpy="0 0 0" xyz="0 0 0" />
            <geometry>
                <mesh filename="package://fanuc_lrmate200id_support/meshes/lrmate200id/visual/link_3.stl" />
            </geometry>
            <material name="">
                <color rgba="0.96 0.76 0.13 1.0" />
            </material>
        </visual>
        <collision>
            <origin rpy="0 0 0" xyz="0 0 0" />
            <geometry>
                <mesh filename="package://fanuc_lrmate200id_support/meshes/lrmate200id/collision/link_3.stl" />
            </geometry>
        </collision>
        <inertial>
            <origin rpy="0 0 0" xyz="0 0 0" />
            <mass value="1.0" />
            <inertia ixx="0.005" ixy="0.0" ixz="0.0" iyy="0.005" iyz="0.0" izz="0.005" />
        </inertial>
    </link>
    <link name="link_4">
        <visual>
            <origin rpy="0 0 0" xyz="0 0 0" />
            <geometry>
                <mesh filename="package://fanuc_lrmate200id_support/meshes/lrmate200id/visual/link_4.stl" />
            </geometry>
            <material name="">
                <color rgba="0.96 0.76 0.13 1.0" />
            </material>
        </visual>
        <collision>
            <origin rpy="0 0 0" xyz="0 0 0" />
            <geometry>
                <mesh filename="package://fanuc_lrmate200id_support/meshes/lrmate200id/collision/link_4.stl" />
            </geometry>
        </collision>
        <inertial>
            <origin rpy="0 0 0" xyz="0 0 0" />
            <mass value="1.2" />
            <inertia ixx="0.007" ixy="0.0" ixz="0.0" iyy="0.007" iyz="0.0" izz="0.007" />
        </inertial>
    </link>
    <link name="link_5">
        <visual>
            <origin rpy="0 0 0" xyz="0 0 0" />
            <geometry>
                <mesh filename="package://fanuc_lrmate200id_support/meshes/lrmate200id/visual/link_5.stl" />
            </geometry>
            <material name="">
                <color rgba="0.96 0.76 0.13 1.0" />
            </material>
        </visual>
        <collision>
            <origin rpy="0 0 0" xyz="0 0 0" />
            <geometry>
                <mesh filename="package://fanuc_lrmate200id_support/meshes/lrmate200id/collision/link_5.stl" />
            </geometry>
        </collision>
        <inertial>
            <origin rpy="0 0 0" xyz="0 0 0" />
            <mass value="0.8" />
            <inertia ixx="0.003" ixy="0.0" ixz="0.0" iyy="0.003" iyz="0.0" izz="0.003" />
        </inertial>
    </link>
    <link name="link_6">
        <visual>
            <origin rpy="0 0 0" xyz="0 0 0" />
            <geometry>
                <mesh filename="package://fanuc_lrmate200id_support/meshes/lrmate200id/visual/link_6.stl" />
            </geometry>
            <material name="">
                <color rgba="0.15 0.15 0.15 1.0" />
            </material>
        </visual>
        <collision>
            <origin rpy="0 0 0" xyz="0 0 0" />
            <geometry>
                <mesh filename="package://fanuc_lrmate200id_support/meshes/lrmate200id/collision/link_6.stl" />
            </geometry>
        </collision>
        <inertial>
            <origin rpy="0 0 0" xyz="0 0 0" />
            <mass value="0.5" />
            <inertia ixx="0.002" ixy="0.0" ixz="0.0" iyy="0.002" iyz="0.0" izz="0.002" />
        </inertial>
    </link>
    <link name="gripper_link">
        <visual>
            <geometry>
                <mesh filename="package://moveit_resources_panda_description/meshes/visual/hand.dae" />
            </geometry>
        </visual>
        <collision>
            <geometry>
                <mesh filename="package://moveit_resources_panda_description/meshes/collision/hand.stl" />
            </geometry>
        </collision>
        <inertial>
            <origin rpy="0 0 0" xyz="0 0 0" />
            <mass value="0.3" />
            <inertia ixx="0.001" ixy="0.0" ixz="0.0" iyy="0.001" iyz="0.0" izz="0.001" />
        </inertial>
    </link>
    <link name="leftfinger">
        <visual>
            <geometry>
                <mesh filename="package://moveit_resources_panda_description/meshes/visual/finger.dae" />
            </geometry>
        </visual>
        <collision>
            <geometry>
                <mesh filename="package://moveit_resources_panda_description/meshes/collision/finger.stl" />
            </geometry>
        </collision>
        <inertial>
            <origin rpy="0 0 0" xyz="0 0 0" />
            <mass value="0.1" />
            <origin rpy="0 0 0" xyz="0 0 0" />
            <inertia ixx="0.03" ixy="0.0" ixz="0.0" iyy="0.03" iyz="0.0" izz="0.03" />
        </inertial>
    </link>
    <link name="rightfinger">
        <visual>
            <origin rpy="0 0 3.141592653589793" xyz="0 0 0" />
            <geometry>
                <mesh filename="package://moveit_resources_panda_description/meshes/visual/finger.dae" />
            </geometry>
        </visual>
        <collision>
            <origin rpy="0 0 3.141592653589793" xyz="0 0 0" />
            <geometry>
                <mesh filename="package://moveit_resources_panda_description/meshes/collision/finger.stl" />
            </geometry>
        </collision>
        <inertial>
            <origin rpy="0 0 0" xyz="0 0 0" />
            <mass value="0.1" />
            <origin rpy="0 0 0" xyz="0 0 0" />
            <inertia ixx="0.03" ixy="0.0" ixz="0.0" iyy="0.03" iyz="0.0" izz="0.03" />
        </inertial>
    </link>
    <!--#######################################JOINT#######################################-->
    <joint name="joint_1" type="revolute">
        <origin rpy="0 0 0" xyz="0 0 0.330" />
        <parent link="base_link" />
        <child link="link_1" />
        <axis xyz="0 0 1" />
        <limit effort="0" lower="-2.9670597283903604" upper="2.9670597283903604" velocity="7.853981633974483" />
        <dynamics damping="20" friction="0.1" />
    </joint>
    <joint name="joint_2" type="revolute">
        <origin rpy="0 0 0" xyz="0.050 0 0" />
        <parent link="link_1" />
        <child link="link_2" />
        <axis xyz="0 1 0" />
        <limit effort="0" lower="-1.7453292519943295" upper="2.530727415391778" velocity="6.632251157578453" />
        <dynamics damping="20" friction="0.1" />
    </joint>
    <joint name="joint_3" type="revolute">
        <origin rpy="0 0 0" xyz="0 0 0.330" />
        <parent link="link_2" />
        <child link="link_3" />
        <axis xyz="0 -1 0" />
        <limit effort="0" lower="-1.2217304763960306" upper="3.5779249665883754" velocity="9.075712110370514" />
        <dynamics damping="20" friction="0.1" />
    </joint>
    <joint name="joint_4" type="revolute">
        <origin rpy="0 0 0" xyz="0 0 0.035" />
        <parent link="link_3" />
        <child link="link_4" />
        <axis xyz="-1 0 0" />
        <limit effort="0" lower="-3.3161255787892263" upper="3.3161255787892263" velocity="9.599310885968812" />
        <dynamics damping="20" friction="0.1" />
    </joint>
    <joint name="joint_5" type="revolute">
        <origin rpy="0 0 0" xyz="0.335 0 0" />
        <parent link="link_4" />
        <child link="link_5" />
        <axis xyz="0 -1 0" />
        <limit effort="0" lower="-2.181661564992912" upper="2.181661564992912" velocity="9.512044423369096" />
        <dynamics damping="20" friction="0.1" />
    </joint>
    <joint name="joint_6" type="revolute">
        <origin rpy="0 0 0" xyz="0.080 0 0" />
        <parent link="link_5" />
        <child link="link_6" />
        <axis xyz="-1 0 0" />
        <limit effort="0" lower="-6.283185307179586" upper="6.283185307179586" velocity="17.453292519943297" />
        <dynamics damping="20" friction="0.1" />
    </joint>
    <joint name="link_6_gripper_link" type="fixed">
        <origin rpy="3.141592653589793 -1.5707963267948966 0" xyz="0 0 0" />
        <parent link="link_6" />
        <child link="gripper_link" />
        <dynamics damping="20" friction="0.1" />
    </joint>
    <joint name="finger_joint_1" type="prismatic">
        <parent link="gripper_link" />
        <child link="leftfinger" />
        <origin rpy="0 0 0" xyz="0 0 0.0584" />
        <axis xyz="0 1 0" />
        <limit effort="20" lower="0.0" upper="0.04" velocity="0.2" />
        <dynamics damping="20" friction="0.1" />
    </joint>
    <joint name="finger_joint_2" type="prismatic">
        <parent link="gripper_link" />
        <child link="rightfinger" />
        <origin rpy="0 0 0" xyz="0 0 0.0584" />
        <axis xyz="0 -1 0" />
        <limit effort="20" lower="0.0" upper="0.04" velocity="0.2" />
        <mimic joint="finger_joint_1" />
        <dynamics damping="20" friction="0.1" />
    </joint>
    <!--##########################################TRANS####################################-->
    <transmission name="joint_1_trans">
        <provideFeedback>true</provideFeedback>
        <implicitSpringDamper>0</implicitSpringDamper>
        <motorTorqueConstant>0.418</motorTorqueConstant>
        <type>transmission_interface/SimpleTransmission</type>
        <joint name="joint_1">
            <hardwareInterface>hardware_interface/PositionJointInterface</hardwareInterface>
        </joint>
        <actuator name="joint_1_motor">
            <hardwareInterface>hardware_interface/PositionJointInterface</hardwareInterface>
            <mechanicalReduction>1</mechanicalReduction>
        </actuator>
    </transmission>
    <transmission name="joint_2_trans">
        <provideFeedback>true</provideFeedback>
        <implicitSpringDamper>0</implicitSpringDamper>
        <motorTorqueConstant>0.418</motorTorqueConstant>
        <type>transmission_interface/SimpleTransmission</type>
        <joint name="joint_2">
            <hardwareInterface>hardware_interface/PositionJointInterface</hardwareInterface>
        </joint>
        <actuator name="joint_2_motor">
            <hardwareInterface>hardware_interface/PositionJointInterface</hardwareInterface>
            <mechanicalReduction>1</mechanicalReduction>
        </actuator>
    </transmission>
    <transmission name="joint_3_trans">
        <provideFeedback>true</provideFeedback>
        <implicitSpringDamper>0</implicitSpringDamper>
        <motorTorqueConstant>0.418</motorTorqueConstant>
        <type>transmission_interface/SimpleTransmission</type>
        <joint name="joint_3">
            <hardwareInterface>hardware_interface/PositionJointInterface</hardwareInterface>
        </joint>
        <actuator name="joint_3_motor">
            <hardwareInterface>hardware_interface/PositionJointInterface</hardwareInterface>
            <mechanicalReduction>1</mechanicalReduction>
        </actuator>
    </transmission>
    <transmission name="joint_4_trans">
        <provideFeedback>true</provideFeedback>
        <implicitSpringDamper>0</implicitSpringDamper>
        <motorTorqueConstant>0.418</motorTorqueConstant>
        <type>transmission_interface/SimpleTransmission</type>
        <joint name="joint_4">
            <hardwareInterface>hardware_interface/PositionJointInterface</hardwareInterface>
        </joint>
        <actuator name="joint_4_motor">
            <hardwareInterface>hardware_interface/PositionJointInterface</hardwareInterface>
            <mechanicalReduction>1</mechanicalReduction>
        </actuator>
    </transmission>
    <transmission name="joint_5_trans">
        <provideFeedback>true</provideFeedback>
        <implicitSpringDamper>0</implicitSpringDamper>
        <motorTorqueConstant>0.418</motorTorqueConstant>
        <type>transmission_interface/SimpleTransmission</type>
        <joint name="joint_5">
            <hardwareInterface>hardware_interface/PositionJointInterface</hardwareInterface>
        </joint>
        <actuator name="joint_5_motor">
            <hardwareInterface>hardware_interface/PositionJointInterface</hardwareInterface>
            <mechanicalReduction>1</mechanicalReduction>
        </actuator>
    </transmission>
    <transmission name="joint_6_trans">
        <provideFeedback>true</provideFeedback>
        <implicitSpringDamper>0</implicitSpringDamper>
        <motorTorqueConstant>0.418</motorTorqueConstant>
        <type>transmission_interface/SimpleTransmission</type>
        <joint name="joint_6">
            <hardwareInterface>hardware_interface/PositionJointInterface</hardwareInterface>
        </joint>
        <actuator name="joint_6_motor">
            <hardwareInterface>hardware_interface/PositionJointInterface</hardwareInterface>
            <mechanicalReduction>1</mechanicalReduction>
        </actuator>
    </transmission>
    <transmission name="trans_finger_joint_1">
        <type>transmission_interface/SimpleTransmission</type>
        <joint name="finger_joint_1">
            <hardwareInterface>hardware_interface/PositionJointInterface</hardwareInterface>
        </joint>
        <actuator name="finger_joint_1_motor">
            <hardwareInterface>hardware_interface/PositionJointInterface</hardwareInterface>
            <mechanicalReduction>1</mechanicalReduction>
        </actuator>
    </transmission>
    <transmission name="trans_finger_joint_2">
        <type>transmission_interface/SimpleTransmission</type>
        <joint name="finger_joint_2">
            <hardwareInterface>hardware_interface/PositionJointInterface</hardwareInterface>
        </joint>
        <actuator name="finger_joint_2_motor">
            <hardwareInterface>hardware_interface/PositionJointInterface</hardwareInterface>
            <mechanicalReduction>1</mechanicalReduction>
        </actuator>
    </transmission>
    <!--####################################GAZEBO_COLOR##########################################-->
    <gazebo reference="base_link">
        <material>Gazebo/Black</material>
        <selfCollide>true</selfCollide>
    </gazebo>
    <gazebo reference="link_1">
        <material>Gazebo/Yellow</material>
        <selfCollide>true</selfCollide>
    </gazebo>
    <gazebo reference="link_2">
        <material>Gazebo/Yellow</material>
        <selfCollide>true</selfCollide>
    </gazebo>
    <gazebo reference="link_3">
        <material>Gazebo/Yellow</material>
        <selfCollide>true</selfCollide>
    </gazebo>
    <gazebo reference="link_4">
        <material>Gazebo/Yellow</material>
        <selfCollide>true</selfCollide>
    </gazebo>
    <gazebo reference="link_5">
        <material>Gazebo/Yellow</material>
        <selfCollide>true</selfCollide>
    </gazebo>
    <gazebo reference="link_6">
        <material>Gazebo/Yellow</material>
        <selfCollide>true</selfCollide>
    </gazebo>
    <gazebo reference="gripper_link">
        <material>Gazebo/Black</material>
        <selfCollide>true</selfCollide>
    </gazebo>
    <gazebo reference="leftfinger">
        <material>Gazebo/Black</material>
        <selfCollide>true</selfCollide>
    </gazebo>
    <gazebo reference="rightfinger">
        <material>Gazebo/Black</material>
        <selfCollide>true</selfCollide>
    </gazebo>
</robot>

